[
  {
    "id": "BUG-bb2b81a1",
    "title": "数据库连接超时问题",
    "description": "这是一个关于数据库连接超时问题的详细描述。问题出现在系统运行过程中，影响了正常功能的使用。",
    "reproducible": true,
    "steps_to_reproduce": [
      "1. 启动系统",
      "2. 执行特定操作",
      "3. 观察错误现象"
    ],
    "expected_behavior": "系统应该正常运行并返回预期结果",
    "actual_behavior": "系统出现数据库连接超时问题，导致功能异常",
    "code_context": {
      "code": "def connect_db():\n    try:\n        connection = psycopg2.connect(\n            dbname=\"testdb\",\n            user=\"admin\",\n            password=\"secret\",\n            host=\"localhost\",\n            port=\"5432\"\n        )\n        return connection\n    except Exception as e:\n        logger.error(f\"数据库连接失败: {str(e)}\")\n        raise",
      "file_path": "src/features/feature_1.py",
      "line_range": [
        66,
        71
      ],
      "language": "Python"
    },
    "error_logs": "Connection timeout after 30 seconds",
    "environment": {
      "runtime_env": "Python 3.8.10",
      "os_info": "Ubuntu 20.04 LTS",
      "network_env": "内网环境"
    },
    "created_at": "2025-02-15T08:16:07.542147",
    "updated_at": "2025-02-15T15:16:07.542147"
  },
  {
    "id": "BUG-0ae5e927",
    "title": "用户登录失败",
    "description": "这是一个关于用户登录失败的详细描述。问题出现在系统运行过程中，影响了正常功能的使用。",
    "reproducible": false,
    "steps_to_reproduce": [
      "1. 启动系统",
      "2. 执行特定操作",
      "3. 观察错误现象"
    ],
    "expected_behavior": "系统应该正常运行并返回预期结果",
    "actual_behavior": "系统出现用户登录失败，导致功能异常",
    "code_context": {
      "code": "async def login_user(username: str, password: str):\n    user = await db.users.find_one({\"username\": username})\n    if not user or not verify_password(password, user[\"password\"]):\n        raise AuthenticationError(\"用户名或密码错误\")\n    return generate_token(user)",
      "file_path": "src/features/feature_2.py",
      "line_range": [
        55,
        66
      ],
      "language": "Python"
    },
    "error_logs": "Invalid credentials provided",
    "environment": {
      "runtime_env": "Node.js 14.17.0",
      "os_info": "Windows 10 Pro",
      "network_env": "公网环境"
    },
    "created_at": "2025-03-10T08:16:07.542147",
    "updated_at": "2025-03-11T01:16:07.542147"
  },
  {
    "id": "BUG-98ca96dd",
    "title": "文件上传大小限制异常",
    "description": "这是一个关于文件上传大小限制异常的详细描述。问题出现在系统运行过程中，影响了正常功能的使用。",
    "reproducible": false,
    "steps_to_reproduce": [
      "1. 启动系统",
      "2. 执行特定操作",
      "3. 观察错误现象"
    ],
    "expected_behavior": "系统应该正常运行并返回预期结果",
    "actual_behavior": "系统出现文件上传大小限制异常，导致功能异常",
    "code_context": {
      "code": "def upload_file(file: UploadFile):\n    if file.size > MAX_FILE_SIZE:\n        raise FileTooLargeError(\"文件大小超过限制\")\n    return save_file(file)",
      "file_path": "src/features/feature_3.py",
      "line_range": [
        50,
        68
      ],
      "language": "Python"
    },
    "error_logs": "File size exceeds maximum limit of 10MB",
    "environment": {
      "runtime_env": "Java 11.0.12",
      "os_info": "CentOS 7",
      "network_env": "内网环境"
    },
    "created_at": "2025-02-21T08:16:07.542147",
    "updated_at": "2025-02-21T11:16:07.542147"
  },
  {
    "id": "BUG-a95d852b",
    "title": "内存泄漏警告",
    "description": "这是一个关于内存泄漏警告的详细描述。问题出现在系统运行过程中，影响了正常功能的使用。",
    "reproducible": true,
    "steps_to_reproduce": [
      "1. 启动系统",
      "2. 执行特定操作",
      "3. 观察错误现象"
    ],
    "expected_behavior": "系统应该正常运行并返回预期结果",
    "actual_behavior": "系统出现内存泄漏警告，导致功能异常",
    "code_context": {
      "code": "class DataProcessor:\n    def __init__(self):\n        self.cache = {}\n    \n    def process_data(self, data):\n        self.cache[data.id] = data\n        return self.cache",
      "file_path": "src/features/feature_4.py",
      "line_range": [
        20,
        33
      ],
      "language": "Python"
    },
    "error_logs": "Memory usage exceeds 80% threshold",
    "environment": {
      "runtime_env": "Python 3.9.7",
      "os_info": "macOS 11.6",
      "network_env": "开发环境"
    },
    "created_at": "2025-03-16T08:16:07.542147",
    "updated_at": "2025-03-16T11:16:07.542147"
  },
  {
    "id": "BUG-c081b0fa",
    "title": "API 响应延迟",
    "description": "这是一个关于API 响应延迟的详细描述。问题出现在系统运行过程中，影响了正常功能的使用。",
    "reproducible": false,
    "steps_to_reproduce": [
      "1. 启动系统",
      "2. 执行特定操作",
      "3. 观察错误现象"
    ],
    "expected_behavior": "系统应该正常运行并返回预期结果",
    "actual_behavior": "系统出现API 响应延迟，导致功能异常",
    "code_context": {
      "code": "@app.get(\"/api/data\")\nasync def get_data():\n    await asyncio.sleep(2)  # 模拟延迟\n    return {\"status\": \"success\"}",
      "file_path": "src/features/feature_5.py",
      "line_range": [
        83,
        95
      ],
      "language": "Python"
    },
    "error_logs": "API response time exceeds 500ms",
    "environment": {
      "runtime_env": "Go 1.16.7",
      "os_info": "Windows Server 2019",
      "network_env": "生产环境"
    },
    "created_at": "2025-02-22T08:16:07.542147",
    "updated_at": "2025-02-22T11:16:07.542147"
  },
  {
    "id": "BUG-af382d67",
    "title": "缓存更新失败",
    "description": "这是一个关于缓存更新失败的详细描述。问题出现在系统运行过程中，影响了正常功能的使用。",
    "reproducible": false,
    "steps_to_reproduce": [
      "1. 启动系统",
      "2. 执行特定操作",
      "3. 观察错误现象"
    ],
    "expected_behavior": "系统应该正常运行并返回预期结果",
    "actual_behavior": "系统出现缓存更新失败，导致功能异常",
    "code_context": {
      "code": "def update_cache(key: str, value: Any):\n    try:\n        redis_client.set(key, value)\n    except Exception as e:\n        logger.error(f\"缓存更新失败: {str(e)}\")\n        raise",
      "file_path": "src/features/feature_6.py",
      "line_range": [
        26,
        35
      ],
      "language": "Python"
    },
    "error_logs": "Failed to update Redis cache",
    "environment": {
      "runtime_env": "Python 3.7.9",
      "os_info": "Debian 10",
      "network_env": "测试环境"
    },
    "created_at": "2025-02-28T08:16:07.542147",
    "updated_at": "2025-02-28T20:16:07.542147"
  },
  {
    "id": "BUG-7841e777",
    "title": "并发请求处理错误",
    "description": "这是一个关于并发请求处理错误的详细描述。问题出现在系统运行过程中，影响了正常功能的使用。",
    "reproducible": true,
    "steps_to_reproduce": [
      "1. 启动系统",
      "2. 执行特定操作",
      "3. 观察错误现象"
    ],
    "expected_behavior": "系统应该正常运行并返回预期结果",
    "actual_behavior": "系统出现并发请求处理错误，导致功能异常",
    "code_context": {
      "code": "async def handle_request(request):\n    async with semaphore:\n        return await process_request(request)",
      "file_path": "src/features/feature_7.py",
      "line_range": [
        74,
        86
      ],
      "language": "Python"
    },
    "error_logs": "Concurrent request limit exceeded",
    "environment": {
      "runtime_env": "Node.js 16.13.0",
      "os_info": "Ubuntu 18.04 LTS",
      "network_env": "内网环境"
    },
    "created_at": "2025-02-28T08:16:07.542147",
    "updated_at": "2025-02-28T22:16:07.542147"
  },
  {
    "id": "BUG-637434ee",
    "title": "日志记录异常",
    "description": "这是一个关于日志记录异常的详细描述。问题出现在系统运行过程中，影响了正常功能的使用。",
    "reproducible": false,
    "steps_to_reproduce": [
      "1. 启动系统",
      "2. 执行特定操作",
      "3. 观察错误现象"
    ],
    "expected_behavior": "系统应该正常运行并返回预期结果",
    "actual_behavior": "系统出现日志记录异常，导致功能异常",
    "code_context": {
      "code": "def log_error(error: Exception):\n    try:\n        with open(\"error.log\", \"a\") as f:\n            f.write(f\"{datetime.now()}: {str(error)}\\n\")\n    except Exception as e:\n        print(f\"日志记录失败: {str(e)}\")",
      "file_path": "src/features/feature_8.py",
      "line_range": [
        24,
        35
      ],
      "language": "Python"
    },
    "error_logs": "Failed to write to log file",
    "environment": {
      "runtime_env": "Java 8.0.301",
      "os_info": "Windows 10 Enterprise",
      "network_env": "开发环境"
    },
    "created_at": "2025-02-26T08:16:07.542147",
    "updated_at": "2025-02-26T11:16:07.542147"
  },
  {
    "id": "BUG-c6cf5a59",
    "title": "数据同步失败",
    "description": "这是一个关于数据同步失败的详细描述。问题出现在系统运行过程中，影响了正常功能的使用。",
    "reproducible": true,
    "steps_to_reproduce": [
      "1. 启动系统",
      "2. 执行特定操作",
      "3. 观察错误现象"
    ],
    "expected_behavior": "系统应该正常运行并返回预期结果",
    "actual_behavior": "系统出现数据同步失败，导致功能异常",
    "code_context": {
      "code": "def sync_data(source: str, target: str):\n    data = fetch_data(source)\n    try:\n        save_data(target, data)\n    except Exception as e:\n        logger.error(f\"数据同步失败: {str(e)}\")\n        raise",
      "file_path": "src/features/feature_9.py",
      "line_range": [
        19,
        37
      ],
      "language": "Python"
    },
    "error_logs": "Data synchronization timeout",
    "environment": {
      "runtime_env": "Python 3.10.0",
      "os_info": "macOS 12.0",
      "network_env": "测试环境"
    },
    "created_at": "2025-03-06T08:16:07.542147",
    "updated_at": "2025-03-06T10:16:07.542147"
  },
  {
    "id": "BUG-3802ae05",
    "title": "权限验证问题",
    "description": "这是一个关于权限验证问题的详细描述。问题出现在系统运行过程中，影响了正常功能的使用。",
    "reproducible": true,
    "steps_to_reproduce": [
      "1. 启动系统",
      "2. 执行特定操作",
      "3. 观察错误现象"
    ],
    "expected_behavior": "系统应该正常运行并返回预期结果",
    "actual_behavior": "系统出现权限验证问题，导致功能异常",
    "code_context": {
      "code": "def check_permission(user: User, resource: str):\n    if not user.has_permission(resource):\n        raise PermissionError(\"没有访问权限\")\n    return True",
      "file_path": "src/features/feature_10.py",
      "line_range": [
        86,
        99
      ],
      "language": "Python"
    },
    "error_logs": "Insufficient permissions for operation",
    "environment": {
      "runtime_env": "Go 1.17.5",
      "os_info": "CentOS 8",
      "network_env": "生产环境"
    },
    "created_at": "2025-03-03T08:16:07.542147",
    "updated_at": "2025-03-03T20:16:07.542147"
  }
]